<?xml version="1.0"?>
<robot name="my_robot">
<!--   <link name="link1">
    <collision>
      <origin xyz="0 0 1" rpy="0 0 0"/>
      <geometry>
        <box size="1 1 2"/>
      </geometry>
    </collision>

    <visual>
      <origin xyz="0 0 1" rpy="0 0 0"/>
      <geometry>
        <box size="1 1 2"/>
      </geometry>
      <material name="orange"/>
    </visual>

    <inertial>
      <origin xyz="0 0 1" rpy="0 0 0"/>
      <mass value="1"/>
      <inertia
        ixx="1.0" ixy="0.0" ixz="0.0"
        iyy="1.0" iyz="0.0"
        izz="1.0"/>
    </inertial>
  </link>
 -->

  <link name="base_link">
    <visual>
      <geometry>
        <box size="0.6 0.4 0.1"/>
      </geometry>
    </visual>
  </link>

  <link name="front_left_wheel">
    <visual>
      <origin xyz="0 0 0" rpy="${pi/2} 0 0" />
      <geometry>
        <cylinder length="0.05" radius="0.1"/>
      </geometry>
    </visual>
  </link>

  <joint name="front_left_wheel_joint" type="continuous">
    <parent link="base_link"/>
    <child link="front_left_wheel"/>
    <origin xyz="0.25 0.25 0" rpy="0 0 0"/>
    <axis xyz="0 1 0"/>
  </joint>

</robot>
